Workbook

Sheet Summary
A1: Awesome MLIPs Benchmark — Curated Database Summary
A2: Last verified | B2: 2026-09-29
A4: KPI | B4: Value | D4: Category | E4: Count | G4: Year | H4: Count
A5: Total normalized records | B5: =COUNTA('Benchmark Index'!A:A)-1 | D5: Batteries, diffusion and ion transport | E5: =COUNTIF('Benchmark Index'!G:G,D5) | G5: 2026 | H5: =COUNTIF('Benchmark Index'!D:D,G5)
A6: Unique existing records | B6: =COUNTIF('Benchmark Index'!V:V,"Yes") | D6: Benchmark suites and platforms | E6: =COUNTIF('Benchmark Index'!G:G,D6) | G6: 2025 | H6: =COUNTIF('Benchmark Index'!D:D,G6)
A7: New additions | B7: =COUNTIF('Benchmark Index'!V:V,"No") | D7: Broader atomistic ML benchmarks | E7: =COUNTIF('Benchmark Index'!G:G,D7) | G7: 2024 | H7: =COUNTIF('Benchmark Index'!D:D,G7)
A8: Core resources | B8: =COUNTIF('Benchmark Index'!F:F,"Core") | D8: Crystal search, stability and generation | E8: =COUNTIF('Benchmark Index'!G:G,D8) | G8: 2023 | H8: =COUNTIF('Benchmark Index'!D:D,G8)
A9: Supporting resources | B9: =COUNTIF('Benchmark Index'!F:F,"Supporting") | D9: Defects, disorder and dimensionality | E9: =COUNTIF('Benchmark Index'!G:G,D9) | G9: 2021 | H9: =COUNTIF('Benchmark Index'!D:D,G9)
D10: Downstream electronic properties | E10: =COUNTIF('Benchmark Index'!G:G,D10) | G10: 2020 | H10: =COUNTIF('Benchmark Index'!D:D,G10)
D11: Dynamics and finite temperature | E11: =COUNTIF('Benchmark Index'!G:G,D11) | G11: 2019 | H11: =COUNTIF('Benchmark Index'!D:D,G11)
D12: Experimental observables | E12: =COUNTIF('Benchmark Index'!G:G,D12) | G12: 2018 | H12: =COUNTIF('Benchmark Index'!D:D,G12)
D13: Foundation datasets and model ecosystems | E13: =COUNTIF('Benchmark Index'!G:G,D13) | G13: 2017 | H13: =COUNTIF('Benchmark Index'!D:D,G13)
D14: General and foundation MLIP evaluation | E14: =COUNTIF('Benchmark Index'!G:G,D14)
D15: MOFs, zeolites and molecular crystals | E15: =COUNTIF('Benchmark Index'!G:G,D15)
D16: Mechanical and elastic properties | E16: =COUNTIF('Benchmark Index'!G:G,D16)
D17: Methodology, reliability and efficiency | E17: =COUNTIF('Benchmark Index'!G:G,D17)
D18: Molecules, reactions and chemical kinetics | E18: =COUNTIF('Benchmark Index'!G:G,D18)
D19: Phonons, vibrations and thermal | E19: =COUNTIF('Benchmark Index'!G:G,D19)
D20: Surfaces, interfaces and catalysis | E20: =COUNTIF('Benchmark Index'!G:G,D20)
D21: Thermodynamics and phase diagrams | E21: =COUNTIF('Benchmark Index'!G:G,D21)

Sheet Benchmark Index
A1: Record_ID | B1: Original_Zotero_Key | C1: Title | D1: Year | E1: Resource_Type | F1: Scope_Tier | G1: Primary_Category | H1: System_Class | I1: Benchmark_Tasks | J1: Models_Evaluated | K1: Key_Metrics | L1: Reference_Baseline | M1: DOI | N1: URL | O1: Code_URL | P1: Data_URL | Q1: Peer_Reviewed | R1: Open_Source | S1: Source_Status | T1: Curation_Confidence | U1: Last_Verified | V1: In_Current_CSV | W1: README_Priority | X1: Notes
A2: N004 | C2: Benchmarking Universal Machine Learning Interatomic Potentials for Alkali-Ion Battery Kinetics | D2: 2026 | E2: Core benchmark study | F2: Core | G2: Batteries, diffusion and ion transport | H2: Alkali-ion cathodes and solid electrolytes | I2: Migration barriers; finite-temperature diffusion; structural correlations | J2: M3GNet; CHGNet; MatterSim; MACE; SevenNet; GRACE; Orb | K2: Barrier error; diffusivity; diffusion activation behavior | L2: DFT / AIMD | M2: 10.1021/acsmaterialslett.6c00134 | N2: https://doi.org/10.1021/acsmaterialslett.6c00134 | Q2: Yes | R2: Unknown | S2: New literature sweep; web-verified | T2: A | U2: 2026-09-29 | V2: No | W2: High | X2: Combines static barrier and dynamic transport evaluation.
A3: E005 | B3: CB4CC5WC | C3: Benchmarking short-range machine learning potentials for atomistic simulations of metal/electrolyte interfaces | D3: 2026 | E3: Core benchmark study | F3: Core | G3: Batteries, diffusion and ion transport | H3: Metals / alloys / elemental solids | I3: energy/force/stress accuracy | K3: energy/force/stress MAE or RMSE | L3: DFT / reference data (see paper) | N3: https://arxiv.org/abs/2602.22931v1 | Q3: Unknown | R3: Unknown | S3: Existing Zotero bibliography; normalized | T3: B | U3: 2026-09-29 | V3: Yes | W3: Medium
A4: E054 | B4: XCBWIVF3 | C4: Li-P-S Electrolyte Materials as a Benchmark for Machine-Learned Interatomic Potentials | D4: 2026 | E4: Core benchmark study | F4: Core | G4: Batteries, diffusion and ion transport | H4: Battery / ionic materials | I4: energy/force/stress accuracy | K4: energy/force/stress MAE or RMSE | L4: DFT / reference data (see paper) | M4: 10.1021/acs.jctc.5c02006 | N4: https://doi.org/10.1021/acs.jctc.5c02006 | Q4: Yes | R4: Unknown | S4: Existing Zotero bibliography; normalized | T4: B | U4: 2026-09-29 | V4: Yes | W4: Medium
A5: N038 | C5: Performance-Based Selection of Machine Learning Interatomic Potentials for Studying Solid-State Electrolytes | D5: 2026 | E5: Application benchmark study | F5: Core | G5: Batteries, diffusion and ion transport | H5: Li6PS5Cl solid-state electrolyte | I5: Structural; energetic; dynamic properties; disorder and transport | J5: Several pretrained MLIPs | K5: Structure/energy errors; dynamic behavior; Li transport | L5: DFT | M5: 10.1021/acs.chemmater.5c02352 | N5: https://doi.org/10.1021/acs.chemmater.5c02352 | Q5: Yes | R5: Unknown | S5: New literature sweep; web-verified | T5: A | U5: 2026-09-29 | V5: No | W5: High | X5: Highlights energy-force consistency and subtle configurational generalization.
A6: E029 | B6: BLJXRAZH | C6: LAMBench: a benchmark for large atomistic models | D6: 2026 | E6: Benchmark suite + study | F6: Core | G6: Benchmark suites and platforms | H6: Large atomistic models | I6: Large-model evaluation across atomistic tasks | K6: Accuracy and task-specific metrics | L6: DFT / reference data (see paper) | M6: 10.1038/s41524-025-01929-3 | N6: https://www.nature.com/articles/s41524-025-01929-3 | Q6: Yes | R6: Unknown | S6: Existing Zotero bibliography; normalized | T6: B | U6: 2026-09-29 | V6: Yes | W6: High
A7: N001 | C7: Structural benchmarks overlook density-of-states errors in machine-learned interatomic potentials | D7: 2026 | E7: Core benchmark study | F7: Core | G7: Downstream electronic properties | H7: Inorganic solids: oxides, iodides, alloys | I7: Structure relaxation; electronic DOS downstream validation | J7: Multiple universal MLIPs | K7: Structural error; DOS similarity/error; downstream electronic-property fidelity | L7: DFT | M7: 10.1063/5.0339982 | N7: https://doi.org/10.1063/5.0339982 | O7: https://github.com/entropy4energy/2026-mlip-dos-benchmark | P7: https://doi.org/10.1063/5.0339982 | Q7: Yes | R7: Yes | S7: New literature sweep; web-verified | T7: A | U7: 2026-09-29 | V7: No | W7: High | X7: Published 2026-09-23; demonstrates that structural agreement does not guarantee DOS fidelity.
A8: N002 | C8: Benchmarking Machine-Learning Interatomic Potentials for Dynamical Stability in Inorganic Semiconductor Nanocrystals: A CdSe Case Study | D8: 2026 | E8: Core benchmark study | F8: Core | G8: Dynamics and finite temperature | H8: CdSe nanocrystals | I8: Long-time MD stability; uncertainty-guided active learning; runtime | J8: Five GNN MLIPs | K8: 1 ns survival/stability; force error; uncertainty; runtime | L8: DFT / reference trajectories | N8: https://arxiv.org/abs/2609.15299 | Q8: No | R8: Unknown | S8: New literature sweep; web-verified | T8: A | U8: 2026-09-29 | V8: No | W8: High | X8: Submitted 2026-09-14; finite, surface-dominated nanocrystal stress test.
A9: N031 | C9: MeltBench | D9: 2026 | E9: Benchmark suite/platform | F9: Core | G9: Dynamics and finite temperature | H9: Crystalline materials / melting | I9: Melting-point prediction with MLIPs | J9: Universal MLIPs | K9: Melting temperature; failure/stability; computational cost | L9: Experiment / reference simulations | N9: https://jobs.sluschi-mapp.org/meltbench | Q9: No | R9: Unknown | S9: New literature sweep; web-verified | T9: A | U9: 2026-09-29 | V9: No | W9: High | X9: Open benchmark resource with MeltBench-10 and expansion toward larger suites.
A10: E055 | B10: JJ5P426W | C10: UniFFBench: evaluating universal machine learning force fields against experimental measurements | D10: 2026 | E10: Core benchmark study | F10: Core | G10: Experimental observables | H10: Broad materials | I10: MLFF validation against experimental measurements | K10: Experiment-facing property errors | L10: DFT / reference data (see paper) | M10: 10.1038/s43588-026-01019-4 | N10: https://www.nature.com/articles/s43588-026-01019-4 | Q10: Yes | R10: Unknown | S10: Existing Zotero bibliography; normalized | T10: B | U10: 2026-09-29 | V10: Yes | W10: High
A11: E004 | B11: HKMYY76Y | C11: Benchmarking Compositional Generalisation for Machine Learning Interatomic Potentials | D11: 2026 | E11: Core benchmark study | F11: Core | G11: General and foundation MLIP evaluation | H11: Broad / mixed atomistic systems | I11: energy/force/stress accuracy | K11: energy/force/stress MAE or RMSE | L11: DFT / reference data (see paper) | N11: https://arxiv.org/abs/2605.08988v1 | Q11: Unknown | R11: Unknown | S11: Existing Zotero bibliography; normalized | T11: B | U11: 2026-09-29 | V11: Yes | W11: Medium
A12: E070 | B12: SK62D2Q3 | C12: Benchmarking chemically scalable machine-learning interatomic potentials for large-scale simulations of multicomponent alloys | D12: 2026 | E12: Core benchmark study | F12: Core | G12: General and foundation MLIP evaluation | H12: Metals / alloys / elemental solids | I12: energy/force/stress accuracy | K12: energy/force/stress MAE or RMSE | L12: DFT / reference data (see paper) | M12: 10.1103/1qc9-ypyb | N12: https://link.aps.org/doi/10.1103/1qc9-ypyb | Q12: Yes | R12: Unknown | S12: Existing Zotero bibliography; normalized | T12: B | U12: 2026-09-29 | V12: Yes | W12: Medium
A13: E071 | B13: 8TNANSAV | C13: Benchmarking universal machine learning interatomic potentials on elemental systems | D13: 2026 | E13: Core benchmark study | F13: Core | G13: General and foundation MLIP evaluation | H13: Metals / alloys / elemental solids | I13: energy/force/stress accuracy | K13: energy/force/stress MAE or RMSE | L13: DFT / reference data (see paper) | M13: 10.1038/s41524-026-02251-2 | N13: https://www.nature.com/articles/s41524-026-02251-2 | Q13: Yes | R13: Unknown | S13: Existing Zotero bibliography; normalized | T13: B | U13: 2026-09-29 | V13: Yes | W13: Medium
A14: E049 | B14: BYMVNIQR | C14: Dyna-Mat: End-to-end benchmarking of foundation machine learning interatomic potentials in finite-temperature ensembles | D14: 2026 | E14: Core benchmark study | F14: Core | G14: General and foundation MLIP evaluation | H14: Broad / mixed atomistic systems | I14: energy/force/stress accuracy; molecular dynamics / stability | K14: energy/force/stress MAE or RMSE; trajectory stability / physical observables | L14: DFT / reference data (see paper) | M14: 10.48550/arXiv.2607.03433 | N14: http://arxiv.org/abs/2607.03433 | Q14: No | R14: Unknown | S14: Existing Zotero bibliography; normalized | T14: B | U14: 2026-09-29 | V14: Yes | W14: Medium
A15: N008 | C15: Origin of the machine learning forces field errors across metal elements | D15: 2026 | E15: Core benchmark study | F15: Core | G15: General and foundation MLIP evaluation | H15: 43 metallic elements (Metal-43) | I15: Element-wise fitting difficulty; PES complexity | J15: NEP; DeePMD; MACE; ORB | K15: Force RMSE; relative force error; periodic trends | L15: DFT | M15: 10.1038/s41524-026-01977-3 | N15: https://doi.org/10.1038/s41524-026-01977-3 | Q15: Yes | R15: Unknown | S15: New literature sweep; web-verified | T15: A | U15: 2026-09-29 | V15: No | W15: High | X15: Metal-43 exposes strongly element-dependent intrinsic fitting difficulty.
A16: E069 | B16: TRMP2EJA | C16: Benchmark of machine learning force fields for silica zeolites | D16: 2026 | E16: Core benchmark study | F16: Core | G16: MOFs, zeolites and molecular crystals | H16: Zeolites | I16: energy/force/stress accuracy | K16: energy/force/stress MAE or RMSE | L16: DFT / reference data (see paper) | M16: 10.1016/j.micromeso.2026.114157 | N16: https://www.sciencedirect.com/science/article/pii/S1387181126001320 | Q16: Yes | R16: Unknown | S16: Existing Zotero bibliography; normalized | T16: B | U16: 2026-09-29 | V16: Yes | W16: Medium
A17: E007 | B17: MWB4TJR9 | C17: Benchmarking Universal Interatomic Potentials on Zeolite | D17: 2026 | E17: Core benchmark study | F17: Core | G17: MOFs, zeolites and molecular crystals | H17: Zeolites | I17: energy/force/stress accuracy | K17: energy/force/stress MAE or RMSE | L17: DFT / reference data (see paper) | M17: 10.1021/acs.jpcc.5c06812 | N17: https://doi.org/10.1021/acs.jpcc.5c06812 | Q17: Yes | R17: Unknown | S17: Existing Zotero bibliography; normalized | T17: B | U17: 2026-09-29 | V17: Yes | W17: Medium
A18: E090 | B18: 5CM85PG9 | C18: OMC-bench and AtomBit-OMC: task-aligned benchmarks and robust, interpretable machine-learned interatomic potentials for organic molecular crystals | D18: 2026 | E18: Benchmark suite + study | F18: Core | G18: MOFs, zeolites and molecular crystals | H18: Organic molecular crystals | I18: OOD force/stress; lattice dynamics; cocrystal relaxation; polymorph ranking | K18: Force/stress errors; recovery failure; ranking metrics | L18: DFT / reference data (see paper) | M18: 10.1038/s41524-026-02315-3 | N18: https://www.nature.com/articles/s41524-026-02315-3 | Q18: Yes | R18: Unknown | S18: Existing Zotero bibliography; normalized | T18: B | U18: 2026-09-29 | V18: Yes | W18: High
A19: E076 | B19: ER2QR6BA | C19: Evaluating mechanical property prediction across material classes using molecular dynamics simulations with universal machine-learned interatomic potentials | D19: 2026 | E19: Core benchmark study | F19: Core | G19: Mechanical and elastic properties | H19: Molecular / chemical systems | I19: molecular dynamics / stability | K19: trajectory stability / physical observables | L19: DFT / reference data (see paper) | M19: 10.1038/s42004-026-02057-9 | N19: https://www.nature.com/articles/s42004-026-02057-9 | Q19: Yes | R19: Unknown | S19: Existing Zotero bibliography; normalized | T19: B | U19: 2026-09-29 | V19: Yes | W19: Medium
A20: E062 | B20: 8R8G4ZBB | C20: Are Machine Learning Interatomic Potentials Truly Practical? A Benchmark of 23 Mainstream Models | D20: 2026 | E20: Core benchmark study | F20: Core | G20: Methodology, reliability and efficiency | H20: Broad / mixed atomistic systems | I20: energy/force/stress accuracy; efficiency / scaling | K20: energy/force/stress MAE or RMSE; throughput / runtime / memory | L20: DFT / reference data (see paper) | M20: 10.48550/arXiv.2607.07647 | N20: http://arxiv.org/abs/2607.07647 | Q20: No | R20: Unknown | S20: Existing Zotero bibliography; normalized | T20: B | U20: 2026-09-29 | V20: Yes | W20: Medium
A21: E080 | B21: 7IZSWD47 | C21: FPBench: Application-Oriented Error Decomposition for Foundation Potentials | D21: 2026 | E21: Benchmark suite + study | F21: Core | G21: Methodology, reliability and efficiency | H21: Multiple materials tasks | I21: Force decomposition; energy ranking; ion/vacancy migration | K21: Error-decomposition metrics by application-relevant component | L21: DFT / reference data (see paper) | M21: 10.48550/arXiv.2609.05714 | N21: http://arxiv.org/abs/2609.05714 | Q21: No | R21: Unknown | S21: Existing Zotero bibliography; normalized | T21: B | U21: 2026-09-29 | V21: Yes | W21: High
A22: E065 | B22: TPN3Z6MI | C22: Accuracy and Efficiency Benchmarks of Pretrained Machine Learning Potentials for Molecular Simulations | D22: 2026 | E22: Core benchmark study | F22: Core | G22: Molecules, reactions and chemical kinetics | H22: Molecular / chemical systems | I22: energy/force/stress accuracy; molecular dynamics / stability; efficiency / scaling | K22: energy/force/stress MAE or RMSE; trajectory stability / physical observables; throughput / runtime / memory | L22: DFT / reference data (see paper) | M22: 10.1021/acs.jctc.6c00130 | N22: https://doi.org/10.1021/acs.jctc.6c00130 | Q22: Yes | R22: Unknown | S22: Existing Zotero bibliography; normalized | T22: B | U22: 2026-09-29 | V22: Yes | W22: Medium
A23: E066 | B23: CSBRU8M2 | C23: Benchmarking Foundation Potentials against Quantum Chemistry Methods for Predicting Molecular Redox Potentials | D23: 2026 | E23: Core benchmark study | F23: Core | G23: Molecules, reactions and chemical kinetics | H23: Molecular / chemical systems | I23: energy/force/stress accuracy | K23: energy/force/stress MAE or RMSE | L23: DFT / reference data (see paper) | M23: 10.1021/prechem.5c00258 | N23: https://doi.org/10.1021/prechem.5c00258 | Q23: Yes | R23: Unknown | S23: Existing Zotero bibliography; normalized | T23: B | U23: 2026-09-29 | V23: Yes | W23: Medium
A24: E048 | B24: DSJPEKMV | C24: Benchmarking the UMA Foundation Interatomic Potential for Gas-Phase Chemical Kinetics | D24: 2026 | E24: Core benchmark study | F24: Core | G24: Molecules, reactions and chemical kinetics | H24: Broad / mixed atomistic systems | I24: energy/force/stress accuracy | K24: energy/force/stress MAE or RMSE | L24: DFT / reference data (see paper) | M24: 10.1021/acs.jpca.6c01748 | N24: https://doi.org/10.1021/acs.jpca.6c01748 | Q24: Yes | R24: Unknown | S24: Existing Zotero bibliography; normalized | T24: B | U24: 2026-09-29 | V24: Yes | W24: Medium
A25: N003 | C25: Vibrational power spectra as a tool to benchmark universal machine-learning interatomic potentials for molecular systems: the OMOL-1k-MD data set | D25: 2026 | E25: Benchmark dataset + study | F25: Core | G25: Phonons, vibrations and thermal | H25: Molecules and molecular clusters | I25: Finite-temperature AIMD; vibrational power spectra; vibrational free energy | J25: Universal MLIPs | K25: Vibrational spectrum similarity; free-energy error; trajectory fidelity | L25: DFT AIMD | M25: 10.1038/s41524-026-02286-5 | N25: https://doi.org/10.1038/s41524-026-02286-5 | P25: https://huggingface.co/datasets/JSteffen91/OMOL-1k-MD | Q25: Yes | R25: Yes | S25: New literature sweep; web-verified | T25: A | U25: 2026-09-29 | V25: No | W25: High | X25: 1000 systems and roughly 30 million AIMD structures.
A26: N010 | C26: Benchmarking machine-learned potentials for adsorption on Pt and IrO2 surfaces using OC20 and OMat24 | D26: 2026 | E26: Application benchmark study | F26: Core | G26: Surfaces, interfaces and catalysis | H26: Pt and IrO2 surfaces | I26: Adsorption energies; water-splitting intermediates | J26: UMA-OC20; UMA-OMat24 | K26: Adsorption-energy error | L26: Matched DFT flavors | M26: 10.1007/s44371-026-00865-5 | N26: https://doi.org/10.1007/s44371-026-00865-5 | Q26: Yes | R26: Unknown | S26: New literature sweep; web-verified | T26: A | U26: 2026-09-29 | V26: No | W26: High | X26: Separates dataset/DFT-flavor effects for surface adsorption.
A27: E073 | B27: ZA9RF9NI | C27: Benchmarking universal machine learning interatomic potentials for supported nanoparticles: decoupling energy accuracy from structural exploration | D27: 2026 | E27: Core benchmark study | F27: Core | G27: Surfaces, interfaces and catalysis | H27: Broad / mixed atomistic systems | I27: energy/force/stress accuracy | K27: energy/force/stress MAE or RMSE | L27: DFT / reference data (see paper) | M27: 10.1038/s41524-026-02043-8 | N27: https://www.nature.com/articles/s41524-026-02043-8 | Q27: Yes | R27: Unknown | S27: Existing Zotero bibliography; normalized | T27: B | U27: 2026-09-29 | V27: Yes | W27: Medium
A28: E009 | B28: 5VZ6ARUZ | C28: Design, assessment, and application of machine learning potential energy surfaces | D28: 2026 | E28: Core benchmark study | F28: Core | G28: Surfaces, interfaces and catalysis | H28: Surfaces / interfaces / catalysts | I28: energy/force/stress accuracy; surface / adsorption / catalysis | K28: energy/force/stress MAE or RMSE | L28: DFT / reference data (see paper) | M28: 10.1088/2632-2153/ae47b9 | N28: https://doi.org/10.1088/2632-2153/ae47b9 | Q28: Yes | R28: Unknown | S28: Existing Zotero bibliography; normalized | T28: B | U28: 2026-09-29 | V28: Yes | W28: Medium
A29: E027 | B29: VJZUS8ZB | C29: How accurate are foundational machine learning interatomic potentials for heterogeneous catalysis? | D29: 2026 | E29: Core benchmark study | F29: Core | G29: Surfaces, interfaces and catalysis | H29: Alloyed metals; oxides; metal-oxide interfaces | I29: Adsorption; reaction; vacancies; vibrations; structural relaxation | K29: Task-specific energy/property errors across 80 foundation MLIPs | L29: DFT / reference data (see paper) | M29: 10.1063/5.0317672 | N29: https://doi.org/10.1063/5.0317672 | Q29: Yes | R29: Unknown | S29: Existing Zotero bibliography; normalized | T29: B | U29: 2026-09-29 | V29: Yes | W29: High
A30: E087 | B30: 7L3G7LTT | C30: Assessment and Application of Universal Machine Learning Interatomic Potentials in Solid-State Electrolyte Research | D30: 2025 | E30: Core benchmark study | F30: Core | G30: Batteries, diffusion and ion transport | H30: Battery / ionic materials | I30: energy/force/stress accuracy | K30: energy/force/stress MAE or RMSE | L30: DFT / reference data (see paper) | M30: 10.1021/acsmaterialslett.5c00336 | N30: https://doi.org/10.1021/acsmaterialslett.5c00336 | Q30: Yes | R30: Unknown | S30: Existing Zotero bibliography; normalized | T30: B | U30: 2026-09-29 | V30: Yes | W30: Medium
A31: E086 | B31: 52XJX32F | C31: Benchmarking machine learning models for predicting lithium ion migration | D31: 2025 | E31: Core benchmark study | F31: Core | G31: Batteries, diffusion and ion transport | H31: Battery / ionic materials | I31: energy/force/stress accuracy; migration / diffusion | K31: energy/force/stress MAE or RMSE; barrier / diffusion error | L31: DFT / reference data (see paper) | M31: 10.1038/s41524-025-01571-z | N31: https://www.nature.com/articles/s41524-025-01571-z | Q31: Yes | R31: Unknown | S31: Existing Zotero bibliography; normalized | T31: B | U31: 2026-09-29 | V31: Yes | W31: Medium
A32: E013 | B32: 5XBH8Q4W | C32: MLIP Arena: Advancing Fairness and Transparency in Machine Learning Interatomic Potentials via an Open, Accessible Benchmark Platform | D32: 2025 | E32: Benchmark suite/platform | F32: Core | G32: Benchmark suites and platforms | H32: Broad atomistic systems | I32: Open standardized MLIP comparison; leaderboard/platform | K32: Task-dependent benchmark metrics | L32: DFT / reference data (see paper) | M32: 10.48550/arXiv.2509.20630 | N32: http://arxiv.org/abs/2509.20630 | Q32: No | R32: Unknown | S32: Existing Zotero bibliography; normalized | T32: B | U32: 2026-09-29 | V32: Yes | W32: High
A33: N041 | C33: MLIPAudit: A benchmarking tool for Machine Learned Interatomic Potentials | D33: 2025 | E33: Benchmark suite/platform | F33: Core | G33: Benchmark suites and platforms | H33: Small organics, molecular liquids, proteins and flexible peptides | I33: Modular downstream benchmark suite; CLI/GUI; public leaderboard; scaling | J33: UMA-Small; MACE-OFF; MACE-MP and additional models | K33: Per-benchmark 0-1 scores; task metrics; scaling/runtime | L33: Reference quantum/experimental data | N33: https://arxiv.org/abs/2511.20487 | O33: https://github.com/instadeepai/mlipaudit | P33: https://huggingface.co/spaces/InstaDeepAI/mlipaudit-leaderboard | Q33: No | R33: Yes | S33: New literature sweep; web-verified | T33: A | U33: 2026-09-29 | V33: No | W33: High | X33: Open Apache-2.0 benchmark library with reusable ASE-compatible pipeline and continuously updated leaderboard.
A34: E088 | B34: 9U9TATYG | C34: MS25: Materials Science-Focused Benchmark Data Set for Machine Learning Interatomic Potentials | D34: 2025 | E34: Benchmark dataset + study | F34: Core | G34: Benchmark suites and platforms | H34: MgO surfaces; water; zeolites; Pt reaction; HEAs; Zr oxides | I34: E/F/S; observables; transferability; size extensivity | K34: E/F/S errors; lattice; volume; reaction barriers | L34: DFT / reference data (see paper) | M34: 10.1021/acs.jcim.5c01262 | N34: https://doi.org/10.1021/acs.jcim.5c01262 | Q34: Yes | R34: Unknown | S34: Existing Zotero bibliography; normalized | T34: B | U34: 2026-09-29 | V34: Yes | W34: High
A35: N032 | C35: MatCalc | D35: 2025 | E35: Benchmark suite/platform | F35: Core | G35: Benchmark suites and platforms | H35: Inorganic materials | I35: Property calculation and standardized elasticity/phonon benchmarks | J35: Multiple foundation potentials | K35: Elasticity and phonon benchmark metrics | L35: DFT/reference property data | N35: https://matcalc.ai/ | Q35: No | R35: Unknown | S35: New literature sweep; web-verified | T35: A | U35: 2026-09-29 | V35: No | W35: High | X35: Python framework released with MatPES; exposes reusable BenchmarkSuite APIs.
A36: E077 | B36: C9SL78KD | C36: A framework to evaluate machine learning crystal stability predictions | D36: 2025 | E36: Benchmark suite/platform | F36: Core | G36: Crystal search, stability and generation | H36: Inorganic crystals | I36: Discovery/stability evaluation; relaxation; classification | K36: Discovery metrics; stability/classification metrics | L36: DFT / reference data (see paper) | M36: 10.1038/s42256-025-01055-1 | N36: https://www.nature.com/articles/s42256-025-01055-1 | O36: https://github.com/janosh/matbench-discovery | P36: https://matbench-discovery.materialsproject.org/ | Q36: Yes | R36: Yes | S36: Existing Zotero bibliography; normalized | T36: B | U36: 2026-09-29 | V36: Yes | W36: High
A37: E001 | B37: S63RSPX5 | C37: LeMat-GenBench: A Unified Evaluation Framework for Crystal Generative Models | D37: 2025 | E37: Core benchmark study | F37: Core | G37: Crystal search, stability and generation | H37: Inorganic crystals | I37: application-specific evaluation | K37: task-specific metrics | L37: DFT / reference data (see paper) | M37: 10.48550/ARXIV.2512.04562 | N37: https://arxiv.org/abs/2512.04562 | Q37: No | R37: Unknown | S37: Existing Zotero bibliography; normalized | T37: B | U37: 2026-09-29 | V37: Yes | W37: Medium
A38: N009 | C38: Screening of Material Defects using Universal Machine-Learning Interatomic Potentials | D38: 2025 | E38: Application benchmark study | F38: Core | G38: Defects, disorder and dimensionality | H38: Materials Project crystals and 2D materials | I38: Vacancy formation; defective-material screening; simulated etching | J38: Universal MLIPs | K38: Vacancy formation-energy error; hull/stability screening | L38: DFT | M38: 10.1002/smll.202503956 | N38: https://doi.org/10.1002/smll.202503956 | Q38: Yes | R38: Unknown | S38: New literature sweep; web-verified | T38: A | U38: 2026-09-29 | V38: No | W38: High | X38: Includes vacancy calculations for 86,259 materials.
A39: N006 | C39: Universal Machine Learning Potential for Systems with Reduced Dimensionality | D39: 2025 | E39: Core benchmark study | F39: Core | G39: Defects, disorder and dimensionality | H39: 0D, 1D, 2D and 3D systems | I39: Cross-dimensional transferability; structure/energy/force evaluation | J39: Universal MLIPs | K39: Energy/force errors; structural/property transfer | L39: DFT | N39: https://arxiv.org/abs/2508.15614 | Q39: No | R39: Unknown | S39: New literature sweep; web-verified | T39: A | U39: 2026-09-29 | V39: No | W39: High | X39: Highlights dimensionality as a distribution-shift axis.
A40: N007 | C40: Universal machine learning interatomic potentials poised to supplant DFT in modeling general defects in metals and random alloys | D40: 2025 | E40: Core benchmark study | F40: Core | G40: Defects, disorder and dimensionality | H40: Metals and random alloys | I40: Point defects; grain boundaries; random alloys; H-alloy interactions; UQ; efficiency | J40: Universal MLIPs | K40: Defect energies; structural errors; uncertainty correlation; speed | L40: DFT | M40: 10.1088/2632-2153/adea2d | N40: https://doi.org/10.1088/2632-2153/adea2d | Q40: Yes | R40: Unknown | S40: New literature sweep; web-verified | T40: A | U40: 2026-09-29 | V40: No | W40: High | X40: Broad defect-oriented validation in metals and alloys.
...

Sheet New Additions
A1: Record_ID | B1: Original_Zotero_Key | C1: Title | D1: Year | E1: Resource_Type | F1: Scope_Tier | G1: Primary_Category | H1: System_Class | I1: Benchmark_Tasks | J1: Models_Evaluated | K1: Key_Metrics | L1: Reference_Baseline | M1: DOI | N1: URL | O1: Code_URL | P1: Data_URL | Q1: Peer_Reviewed | R1: Open_Source | S1: Source_Status | T1: Curation_Confidence | U1: Last_Verified | V1: In_Current_CSV | W1: README_Priority | X1: Notes
A2: N004 | C2: Benchmarking Universal Machine Learning Interatomic Potentials for Alkali-Ion Battery Kinetics | D2: 2026 | E2: Core benchmark study | F2: Core | G2: Batteries, diffusion and ion transport | H2: Alkali-ion cathodes and solid electrolytes | I2: Migration barriers; finite-temperature diffusion; structural correlations | J2: M3GNet; CHGNet; MatterSim; MACE; SevenNet; GRACE; Orb | K2: Barrier error; diffusivity; diffusion activation behavior | L2: DFT / AIMD | M2: 10.1021/acsmaterialslett.6c00134 | N2: https://doi.org/10.1021/acsmaterialslett.6c00134 | Q2: Yes | R2: Unknown | S2: New literature sweep; web-verified | T2: A | U2: 2026-09-29 | V2: No | W2: High | X2: Combines static barrier and dynamic transport evaluation.
A3: N038 | C3: Performance-Based Selection of Machine Learning Interatomic Potentials for Studying Solid-State Electrolytes | D3: 2026 | E3: Application benchmark study | F3: Core | G3: Batteries, diffusion and ion transport | H3: Li6PS5Cl solid-state electrolyte | I3: Structural; energetic; dynamic properties; disorder and transport | J3: Several pretrained MLIPs | K3: Structure/energy errors; dynamic behavior; Li transport | L3: DFT | M3: 10.1021/acs.chemmater.5c02352 | N3: https://doi.org/10.1021/acs.chemmater.5c02352 | Q3: Yes | R3: Unknown | S3: New literature sweep; web-verified | T3: A | U3: 2026-09-29 | V3: No | W3: High | X3: Highlights energy-force consistency and subtle configurational generalization.
A4: N001 | C4: Structural benchmarks overlook density-of-states errors in machine-learned interatomic potentials | D4: 2026 | E4: Core benchmark study | F4: Core | G4: Downstream electronic properties | H4: Inorganic solids: oxides, iodides, alloys | I4: Structure relaxation; electronic DOS downstream validation | J4: Multiple universal MLIPs | K4: Structural error; DOS similarity/error; downstream electronic-property fidelity | L4: DFT | M4: 10.1063/5.0339982 | N4: https://doi.org/10.1063/5.0339982 | O4: https://github.com/entropy4energy/2026-mlip-dos-benchmark | P4: https://doi.org/10.1063/5.0339982 | Q4: Yes | R4: Yes | S4: New literature sweep; web-verified | T4: A | U4: 2026-09-29 | V4: No | W4: High | X4: Published 2026-09-23; demonstrates that structural agreement does not guarantee DOS fidelity.
A5: N002 | C5: Benchmarking Machine-Learning Interatomic Potentials for Dynamical Stability in Inorganic Semiconductor Nanocrystals: A CdSe Case Study | D5: 2026 | E5: Core benchmark study | F5: Core | G5: Dynamics and finite temperature | H5: CdSe nanocrystals | I5: Long-time MD stability; uncertainty-guided active learning; runtime | J5: Five GNN MLIPs | K5: 1 ns survival/stability; force error; uncertainty; runtime | L5: DFT / reference trajectories | N5: https://arxiv.org/abs/2609.15299 | Q5: No | R5: Unknown | S5: New literature sweep; web-verified | T5: A | U5: 2026-09-29 | V5: No | W5: High | X5: Submitted 2026-09-14; finite, surface-dominated nanocrystal stress test.
A6: N031 | C6: MeltBench | D6: 2026 | E6: Benchmark suite/platform | F6: Core | G6: Dynamics and finite temperature | H6: Crystalline materials / melting | I6: Melting-point prediction with MLIPs | J6: Universal MLIPs | K6: Melting temperature; failure/stability; computational cost | L6: Experiment / reference simulations | N6: https://jobs.sluschi-mapp.org/meltbench | Q6: No | R6: Unknown | S6: New literature sweep; web-verified | T6: A | U6: 2026-09-29 | V6: No | W6: High | X6: Open benchmark resource with MeltBench-10 and expansion toward larger suites.
A7: N008 | C7: Origin of the machine learning forces field errors across metal elements | D7: 2026 | E7: Core benchmark study | F7: Core | G7: General and foundation MLIP evaluation | H7: 43 metallic elements (Metal-43) | I7: Element-wise fitting difficulty; PES complexity | J7: NEP; DeePMD; MACE; ORB | K7: Force RMSE; relative force error; periodic trends | L7: DFT | M7: 10.1038/s41524-026-01977-3 | N7: https://doi.org/10.1038/s41524-026-01977-3 | Q7: Yes | R7: Unknown | S7: New literature sweep; web-verified | T7: A | U7: 2026-09-29 | V7: No | W7: High | X7: Metal-43 exposes strongly element-dependent intrinsic fitting difficulty.
A8: N003 | C8: Vibrational power spectra as a tool to benchmark universal machine-learning interatomic potentials for molecular systems: the OMOL-1k-MD data set | D8: 2026 | E8: Benchmark dataset + study | F8: Core | G8: Phonons, vibrations and thermal | H8: Molecules and molecular clusters | I8: Finite-temperature AIMD; vibrational power spectra; vibrational free energy | J8: Universal MLIPs | K8: Vibrational spectrum similarity; free-energy error; trajectory fidelity | L8: DFT AIMD | M8: 10.1038/s41524-026-02286-5 | N8: https://doi.org/10.1038/s41524-026-02286-5 | P8: https://huggingface.co/datasets/JSteffen91/OMOL-1k-MD | Q8: Yes | R8: Yes | S8: New literature sweep; web-verified | T8: A | U8: 2026-09-29 | V8: No | W8: High | X8: 1000 systems and roughly 30 million AIMD structures.
A9: N010 | C9: Benchmarking machine-learned potentials for adsorption on Pt and IrO2 surfaces using OC20 and OMat24 | D9: 2026 | E9: Application benchmark study | F9: Core | G9: Surfaces, interfaces and catalysis | H9: Pt and IrO2 surfaces | I9: Adsorption energies; water-splitting intermediates | J9: UMA-OC20; UMA-OMat24 | K9: Adsorption-energy error | L9: Matched DFT flavors | M9: 10.1007/s44371-026-00865-5 | N9: https://doi.org/10.1007/s44371-026-00865-5 | Q9: Yes | R9: Unknown | S9: New literature sweep; web-verified | T9: A | U9: 2026-09-29 | V9: No | W9: High | X9: Separates dataset/DFT-flavor effects for surface adsorption.
A10: N041 | C10: MLIPAudit: A benchmarking tool for Machine Learned Interatomic Potentials | D10: 2025 | E10: Benchmark suite/platform | F10: Core | G10: Benchmark suites and platforms | H10: Small organics, molecular liquids, proteins and flexible peptides | I10: Modular downstream benchmark suite; CLI/GUI; public leaderboard; scaling | J10: UMA-Small; MACE-OFF; MACE-MP and additional models | K10: Per-benchmark 0-1 scores; task metrics; scaling/runtime | L10: Reference quantum/experimental data | N10: https://arxiv.org/abs/2511.20487 | O10: https://github.com/instadeepai/mlipaudit | P10: https://huggingface.co/spaces/InstaDeepAI/mlipaudit-leaderboard | Q10: No | R10: Yes | S10: New literature sweep; web-verified | T10: A | U10: 2026-09-29 | V10: No | W10: High | X10: Open Apache-2.0 benchmark library with reusable ASE-compatible pipeline and continuously updated leaderboard.
A11: N032 | C11: MatCalc | D11: 2025 | E11: Benchmark suite/platform | F11: Core | G11: Benchmark suites and platforms | H11: Inorganic materials | I11: Property calculation and standardized elasticity/phonon benchmarks | J11: Multiple foundation potentials | K11: Elasticity and phonon benchmark metrics | L11: DFT/reference property data | N11: https://matcalc.ai/ | Q11: No | R11: Unknown | S11: New literature sweep; web-verified | T11: A | U11: 2026-09-29 | V11: No | W11: High | X11: Python framework released with MatPES; exposes reusable BenchmarkSuite APIs.
A12: N009 | C12: Screening of Material Defects using Universal Machine-Learning Interatomic Potentials | D12: 2025 | E12: Application benchmark study | F12: Core | G12: Defects, disorder and dimensionality | H12: Materials Project crystals and 2D materials | I12: Vacancy formation; defective-material screening; simulated etching | J12: Universal MLIPs | K12: Vacancy formation-energy error; hull/stability screening | L12: DFT | M12: 10.1002/smll.202503956 | N12: https://doi.org/10.1002/smll.202503956 | Q12: Yes | R12: Unknown | S12: New literature sweep; web-verified | T12: A | U12: 2026-09-29 | V12: No | W12: High | X12: Includes vacancy calculations for 86,259 materials.
A13: N006 | C13: Universal Machine Learning Potential for Systems with Reduced Dimensionality | D13: 2025 | E13: Core benchmark study | F13: Core | G13: Defects, disorder and dimensionality | H13: 0D, 1D, 2D and 3D systems | I13: Cross-dimensional transferability; structure/energy/force evaluation | J13: Universal MLIPs | K13: Energy/force errors; structural/property transfer | L13: DFT | N13: https://arxiv.org/abs/2508.15614 | Q13: No | R13: Unknown | S13: New literature sweep; web-verified | T13: A | U13: 2026-09-29 | V13: No | W13: High | X13: Highlights dimensionality as a distribution-shift axis.
A14: N007 | C14: Universal machine learning interatomic potentials poised to supplant DFT in modeling general defects in metals and random alloys | D14: 2025 | E14: Core benchmark study | F14: Core | G14: Defects, disorder and dimensionality | H14: Metals and random alloys | I14: Point defects; grain boundaries; random alloys; H-alloy interactions; UQ; efficiency | J14: Universal MLIPs | K14: Defect energies; structural errors; uncertainty correlation; speed | L14: DFT | M14: 10.1088/2632-2153/adea2d | N14: https://doi.org/10.1088/2632-2153/adea2d | Q14: Yes | R14: Unknown | S14: New literature sweep; web-verified | T14: A | U14: 2026-09-29 | V14: No | W14: High | X14: Broad defect-oriented validation in metals and alloys.
A15: N013 | C15: Crash testing machine learning force fields for molecules, materials, and interfaces: model analysis in the TEA Challenge 2023 | D15: 2025 | E15: Benchmark suite + study | F15: Core | G15: Dynamics and finite temperature | H15: Molecules, materials and interfaces | I15: Common-data MLFF training; MD stability; incomplete data; multicomponent/periodic systems | J15: MACE; SO3krates; sGDML; SOAP/GAP; FCHL19* | K15: Accuracy; MD stability; efficiency; task-specific observables | L15: DFT / experiment | M15: 10.1039/D4SC06530A | N15: https://doi.org/10.1039/D4SC06530A | P15: https://doi.org/10.5281/zenodo.10414029 | Q15: Yes | R15: Yes | S15: New literature sweep; web-verified | T15: A | U15: 2026-09-29 | V15: No | W15: High | X15: TEA Challenge 2023 provides same-condition cross-architecture crash tests.
A16: N005 | C16: Benchmarking Universal Machine Learning Interatomic Potentials for Elastic Property Prediction | D16: 2025 | E16: Core benchmark study | F16: Core | G16: Mechanical and elastic properties | H16: Nearly 11,000 inorganic materials | I16: Elastic tensors/moduli; relaxation; targeted fine-tuning | J16: MatterSim; MACE; SevenNet; CHGNet | K16: Elastic-property errors; stability/failure; fine-tuning gains | L16: DFT | N16: https://arxiv.org/abs/2510.22999 | Q16: No | R16: Unknown | S16: New literature sweep; web-verified | T16: A | U16: 2026-09-29 | V16: No | W16: High | X16: Large-scale elastic-property benchmark; manuscript revised in 2026.
A17: N036 | C17: Benchmarking Universal Machine Learning Force Fields with Hydrogen-Bonding Cooperativity | D17: 2025 | E17: Core benchmark study | F17: Core | G17: Molecules, reactions and chemical kinetics | H17: N-methylacetamide H-bonded chains | I17: Many-body cooperativity / induction / dispersion | J17: ANI; MACE-OFF; Orb | K17: Hydrogen-bond cooperativity relative to QM | L17: Quantum chemistry | M17: 10.4208/cicc.2025.90.02 | N17: https://doi.org/10.4208/cicc.2025.90.02 | Q17: Yes | R17: Unknown | S17: New literature sweep; web-verified | T17: A | U17: 2026-09-29 | V17: No | W17: High | X17: Probes cooperative many-body physics that standard molecular test errors can miss.
A18: N037 | C18: Machine learning potentials for alloys: a detailed workflow to predict phase diagrams and benchmark accuracy | D18: 2025 | E18: Application benchmark study | F18: Core | G18: Thermodynamics and phase diagrams | H18: Binary and multicomponent alloys | I18: Phase-diagram prediction; CALPHAD integration; phase classification | J18: GRACE; SevenNet; CHGNet and others | K18: Accuracy; precision; recall; F1 of phase regions; topology agreement | L18: VASP / CALPHAD | M18: 10.1038/s41524-025-01814-z | N18: https://doi.org/10.1038/s41524-025-01814-z | Q18: Yes | R18: Unknown | S18: New literature sweep; web-verified | T18: A | U18: 2026-09-29 | V18: No | W18: High | X18: PhaseForge turns phase-diagram topology into an application-level MLIP benchmark.
A19: N015 | C19: Efficiency, accuracy, and transferability of machine learning potentials: Application to dislocations and cracks in iron | D19: 2024 | E19: Core benchmark study | F19: Core | G19: Defects, disorder and dimensionality | H19: BCC iron | I19: Dislocations; cracks; fracture; uncertainty; efficiency | J19: Four MLIP packages | K19: RMSE; property error Q; Peierls barrier; traction-separation; KIc; speed | L19: DFT | M19: 10.1016/j.actamat.2024.119788 | N19: https://doi.org/10.1016/j.actamat.2024.119788 | O19: https://github.com/leiapple/Potential_benchmark_iron | Q19: Yes | R19: Yes | S19: New literature sweep; web-verified | T19: A | U19: 2026-09-29 | V19: No | W19: High | X19: Three-stage validation from test error to defect transferability.
A20: N023 | C20: Complexity of many-body interactions in transition metals via machine-learned force fields from the TM23 data set | D20: 2024 | E20: Benchmark dataset + study | F20: Core | G20: Foundation datasets and model ecosystems | H20: Transition metals | I20: Element-wise force-field learnability; many-body complexity | J20: Multiple MLFF architectures | K20: Energy/force errors; complexity trends | L20: DFT | M20: 10.1038/s41524-024-01264-z | N20: https://doi.org/10.1038/s41524-024-01264-z | Q20: Yes | R20: Unknown | S20: New literature sweep; web-verified | T20: A | U20: 2026-09-29 | V20: No | W20: High | X20: TM23 is a widely used elemental-transition-metal stress test.
A21: N012 | C21: Benchmarking phonon anharmonicity in machine learning interatomic potentials | D21: 2024 | E21: Core benchmark study | F21: Core | G21: Phonons, vibrations and thermal | H21: ThO2 | I21: Anharmonic force constants; phonon interactions; thermal conductivity | J21: GAP; ANN; GNN | K21: Phonon linewidths; line shifts; thermal conductivity; higher-order agreement | L21: DFT | N21: https://arxiv.org/abs/2402.18891 | Q21: No | R21: Unknown | S21: New literature sweep; web-verified | T21: A | U21: 2026-09-29 | V21: No | W21: High | X21: Explicitly probes anharmonic rather than only harmonic phonons.
A22: N014 | C22: Benchmarking of machine learning interatomic potentials for reactive hydrogen dynamics at metal surfaces | D22: 2024 | E22: Core benchmark study | F22: Core | G22: Surfaces, interfaces and catalysis | H22: H2 scattering on Cu surfaces | I22: Reactive gas-surface dynamics; sticking probabilities; CPU throughput | J22: PaiNN; REANN; MACE; ACE | K22: Energy/force accuracy; time-to-solution; reaction/sticking probabilities | L22: DFT / dynamical observables | M22: 10.1088/2632-2153/ad5f11 | N22: https://doi.org/10.1088/2632-2153/ad5f11 | Q22: Yes | R22: Unknown | S22: New literature sweep; web-verified | T22: A | U22: 2026-09-29 | V22: No | W22: High | X22: Application benchmark couples accuracy to reactive trajectory observables.
A23: N027 | C23: COMP6: A comprehensive benchmark suite for machine learning potentials | D23: 2018 | E23: Benchmark suite + study | F23: Core | G23: Molecules, reactions and chemical kinetics | H23: Diverse organic molecules and conformers | I23: Transferability across molecular datasets and conformers | J23: ANI family and molecular ML potentials | K23: Energy errors across benchmark subsets | L23: Quantum chemistry | M23: 10.1063/1.5023802 | N23: https://doi.org/10.1063/1.5023802 | O23: https://github.com/isayev/COMP6 | Q23: Yes | R23: Yes | S23: New literature sweep; web-verified | T23: A | U23: 2026-09-29 | V23: No | W23: High | X23: Classic cross-domain molecular-potential benchmark suite.
A24: N017 | C24: The Open Materials 2024 (OMat24) inorganic materials dataset and models | D24: 2026 | E24: Benchmark-supporting dataset | F24: Supporting | G24: Foundation datasets and model ecosystems | H24: Inorganic materials across periodic table | I24: Non-equilibrium PES training; model evaluation; discovery/phonon/thermal downstream tests | J24: EquiformerV2/UMA family and baselines | K24: E/F/S errors; Matbench Discovery; softening; downstream properties | L24: DFT | M24: 10.1038/s43588-026-00996-w | N24: https://doi.org/10.1038/s43588-026-00996-w | O24: https://github.com/FAIR-Chem/fairchem | P24: https://huggingface.co/datasets/facebook/OMAT24 | Q24: Yes | R24: Yes | S24: New literature sweep; web-verified | T24: A | U24: 2026-09-29 | V24: No | W24: Medium | X24: Over 110 million DFT calculations; central foundation-model dataset.
A25: N039 | C25: Net force analysis of the B3LYP-D3BJ/DZVP subset of the SPICE dataset: A diagnostic tool for machine learning force fields | D25: 2026 | E25: Methodology / dataset diagnostic | F25: Supporting | G25: Methodology, reliability and efficiency | H25: SPICE molecular subset | I25: Reference-force consistency; size-aware diagnostics | J25: MLFF benchmark baselines | K25: Net force; RMSE; size-controlled statistics | L25: SPICE quantum chemistry | M25: 10.1016/j.jmgm.2026.109522 | N25: https://doi.org/10.1016/j.jmgm.2026.109522 | Q25: Yes | R25: Unknown | S25: New literature sweep; web-verified | T25: A | U25: 2026-09-29 | V25: No | W25: Medium | X25: Dataset-quality diagnostic showing why apparent RMSE gains can be confounded by molecular size.
A26: N029 | C26: MP-ALOE: an r2SCAN dataset for universal machine learning interatomic potentials | D26: 2025 | E26: Benchmark-supporting dataset | F26: Supporting | G26: Foundation datasets and model ecosystems | H26: Inorganic materials, off-equilibrium | I26: Active-learning PES data; off-equilibrium force benchmark | J26: MACE and universal MLIPs | K26: Energy/force errors; off-equilibrium robustness | L26: r2SCAN DFT | M26: 10.1038/s41524-025-01834-9 | N26: https://doi.org/10.1038/s41524-025-01834-9 | O26: https://github.com/matthewkuner/MP-ALOE | P26: https://doi.org/10.6084/m9.figshare.29452190 | Q26: Yes | R26: Yes | S26: New literature sweep; web-verified | T26: A | U26: 2026-09-29 | V26: No | W26: Medium | X26: Nearly one million r2SCAN calculations over 89 elements.
A27: N019 | C27: The Open Catalyst 2025 (OC25) Dataset and Models for Solid-Liquid Interfaces | D27: 2025 | E27: Benchmark-supporting dataset | F27: Supporting | G27: Foundation datasets and model ecosystems | H27: Explicit-solvent solid-liquid interfaces | I27: Solid-liquid interface PES; solvation; off-equilibrium modeling | J27: OC25 baseline/foundation models | K27: Energy; force; solvation-energy errors | L27: DFT | N27: https://arxiv.org/abs/2509.17862 | O27: https://github.com/FAIR-Chem/fairchem | Q27: No | R27: Yes | S27: New literature sweep; web-verified | T27: A | U27: 2026-09-29 | V27: No | W27: Medium | X27: 7.8 million calculations across 1.5 million explicit-solvent environments.
A28: N018 | C28: The Open Molecules 2025 (OMol25) Dataset, Evaluations, and Models | D28: 2025 | E28: Benchmark-supporting dataset | F28: Supporting | G28: Foundation datasets and model ecosystems | H28: Small molecules, biomolecules, metal complexes, electrolytes | I28: Molecular PES training and broad OOD evaluation | J28: UMA molecular models and baselines | K28: Energy/force errors across chemistry splits and downstream evaluations | L28: omegaB97M-V/def2-TZVPD DFT | N28: https://arxiv.org/abs/2505.08762 | O28: https://github.com/FAIR-Chem/fairchem | Q28: No | R28: Yes | S28: New literature sweep; web-verified | T28: A | U28: 2026-09-29 | V28: No | W28: Medium | X28: More than 100 million DFT calculations, 83 elements, systems up to 350 atoms.
A29: N034 | C29: A foundation model for atomistic materials chemistry | D29: 2025 | E29: Foundation-model validation study | F29: Supporting | G29: General and foundation MLIP evaluation | H29: Solids, liquids, gases, reactions, interfaces, protein | I29: Broad zero-shot application suite; fine-tuning | J29: MACE-MP-0 | K29: Application-specific properties; MD stability; fine-tuning data efficiency | L29: DFT / experiment | M29: 10.1063/5.0297006 | N29: https://doi.org/10.1063/5.0297006 | O29: https://github.com/ACEsuit/mace-mp | P29: https://github.com/ACEsuit/mace-mp | Q29: Yes | R29: Yes | S29: New literature sweep; web-verified | T29: A | U29: 2026-09-29 | V29: No | W29: Medium | X29: Broad application appendix is a useful de facto stress-test suite, though this is primarily a model paper.
A30: N030 | C30: Model-free estimation of completeness, uncertainties, and outliers in atomistic machine learning using information theory | D30: 2025 | E30: Methodology / benchmark study | F30: Supporting | G30: Methodology, reliability and efficiency | H30: Molecules, silicon, aluminium, transition metals | I30: Dataset completeness; OOD/outlier detection; uncertainty | J30: Model-free QUESTS framework | K30: Information-theoretic completeness/outlier/UQ metrics | L30: Reference atomistic datasets | M30: 10.1038/s41467-025-59232-0 | N30: https://doi.org/10.1038/s41467-025-59232-0 | O30: https://github.com/dskoda/quests | Q30: Yes | R30: Yes | S30: New literature sweep; web-verified | T30: A | U30: 2026-09-29 | V30: No | W30: Medium | X30: QUESTS evaluates dataset coverage without requiring a trained potential.
A31: N040 | C31: Towards Fast, Specialized Machine Learning Force Fields: Distilling Foundation Models via Energy Hessians | D31: 2025 | E31: Methodology / benchmark study | F31: Supporting | G31: Methodology, reliability and efficiency | H31: OC20, MD22 and SPICE domains | I31: Foundation-model distillation; Hessian matching; MD conservation; speed | J31: Teacher foundation MLFF + compact students | K31: Accuracy; up to 20x speed; MD energy conservation | L31: Foundation teacher / reference datasets | N31: https://arxiv.org/abs/2501.09009 | O31: https://github.com/ASK-Berkeley/MLFF-distill | Q31: No | R31: Yes | S31: New literature sweep; web-verified | T31: A | U31: 2026-09-29 | V31: No | W31: Medium | X31: ICLR 2025; useful efficiency/physicality benchmark for model compression.
A32: N043 | C32: Advancing the ColabFit Exchange towards a Web-scale Data Source for Machine Learning Interatomic Potentials | D32: 2024 | E32: Benchmark-supporting data infrastructure | F32: Supporting | G32: Foundation datasets and model ecosystems | H32: Broad atomistic datasets | I32: Dataset discovery; standardization; exchange for MLIP training and evaluation | J32: Model-agnostic | K32: Dataset coverage and metadata quality | L32: First-principles atomistic datasets | N32: https://openreview.net/forum?id=b8qZpGJIkw | P32: https://colabfit.org/ | Q32: No | R32: Yes | S32: New literature sweep; web-verified | T32: A | U32: 2026-09-29 | V32: No | W32: Medium | X32: Supporting infrastructure rather than a direct leaderboard; useful for benchmark dataset discovery and provenance.
A33: N025 | C33: Expanding the SPICE Dataset with More Molecules and More Conformations | D33: 2024 | E33: Benchmark-supporting dataset | F33: Supporting | G33: Foundation datasets and model ecosystems | H33: Molecules and noncovalent complexes | I33: Expanded molecular PES coverage | J33: Nutmeg / molecular ML potentials | K33: Energy/force benchmark errors | L33: Quantum chemistry | M33: 10.1021/acs.jctc.4c00794 | N33: https://doi.org/10.1021/acs.jctc.4c00794 | O33: https://github.com/openmm/spice-dataset | P33: https://doi.org/10.5281/zenodo.10975225 | Q33: Yes | R33: Yes | S33: New literature sweep; web-verified | T33: A | U33: 2026-09-29 | V33: No | W33: Medium | X33: SPICE 2 / Nutmeg expansion increases chemical and conformational diversity.
A34: N022 | C34: Improving machine-learning models in materials science through large datasets | D34: 2024 | E34: Benchmark-supporting dataset | F34: Supporting | G34: Foundation datasets and model ecosystems | H34: 3D, 2D and 1D inorganic materials | I34: Large-scale DFT training dataset; broad materials evaluation | J34: Dataset-trained ML models | K34: Energy/force/property performance | L34: DFT | M34: 10.1016/j.mtphys.2024.101560 | N34: https://doi.org/10.1016/j.mtphys.2024.101560 | P34: https://alexandria.icams.rub.de/ | Q34: Yes | R34: Yes | S34: New literature sweep; web-verified | T34: A | U34: 2026-09-29 | V34: No | W34: Medium | X34: Alexandria family provides multi-dimensional large-scale DFT data.
A35: N035 | C35: MatterSim: A Deep Learning Atomistic Model Across Elements, Temperatures and Pressures | D35: 2024 | E35: Foundation-model validation study | F35: Supporting | G35: General and foundation MLIP evaluation | H35: Broad inorganic materials; 0-5000 K; up to 1000 GPa | I35: Structures; dynamics; phonons; mechanics; thermodynamics; phase behavior | J35: MatterSim | K35: Energy/force/property errors; Gibbs free energy; phase behavior | L35: DFT / experiment | M35: 10.48550/arXiv.2405.04967 | N35: https://arxiv.org/abs/2405.04967 | O35: https://github.com/microsoft/mattersim | Q35: No | R35: Yes | S35: New literature sweep; web-verified | T35: A | U35: 2026-09-29 | V35: No | W35: Medium | X35: Broad temperature/pressure validation makes it useful as a reference stress-test paper.
A36: N011 | C36: Learning from models: high-dimensional analyses of machine-learned interatomic potentials | D36: 2024 | E36: Methodology / benchmark study | F36: Supporting | G36: Methodology, reliability and efficiency | H36: Multiple material systems | I36: High-dimensional property validation; Pareto analysis | J36: Multiple MLIPs | K36: Property errors; accuracy-efficiency Pareto behavior | L36: DFT / reference properties | M36: 10.1038/s41524-024-01333-3 | N36: https://doi.org/10.1038/s41524-024-01333-3 | O36: https://github.com/mogroupumd/Learning_from_models | Q36: Yes | R36: Yes | S36: New literature sweep; web-verified | T36: A | U36: 2026-09-29 | V36: No | W36: Medium | X36: Useful property-centric benchmark methodology beyond E/F errors.
A37: N016 | C37: Validation workflow for machine learning interatomic potentials for complex ceramics | D37: 2024 | E37: Methodology / benchmark study | F37: Supporting | G37: Methodology, reliability and efficiency | H37: Boron carbide / complex ceramics | I37: Preliminary; static-property; dynamic-property validation | J37: System-specific MLIP | K37: Accuracy; computational efficiency; static/dynamic property errors | L37: DFT / empirical potential | M37: 10.1016/j.commatsci.2024.112983 | N37: https://doi.org/10.1016/j.commatsci.2024.112983 | Q37: Yes | R37: Unknown | S37: New literature sweep; web-verified | T37: A | U37: 2026-09-29 | V37: No | W37: Medium | X37: Reusable three-stage validation workflow demonstrated on B4C.
A38: N033 | C38: CHGNet as a pretrained universal neural network potential for charge-informed atomistic modelling | D38: 2023 | E38: Benchmark-supporting model/dataset | F38: Supporting | G38: Foundation datasets and model ecosystems | H38: Materials Project crystals / MPtrj | I38: Universal potential training and broad materials-property validation | J38: CHGNet | K38: Energy/force/stress; structure; MD/property tests | L38: Materials Project DFT | M38: 10.1038/s42256-023-00716-3 | N38: https://doi.org/10.1038/s42256-023-00716-3 | Q38: Yes | R38: Unknown | S38: New literature sweep; web-verified | T38: A | U38: 2026-09-29 | V38: No | W38: Medium | X38: MPtrj trajectory data became a major training/evaluation source for later foundation potentials.
A39: N020 | C39: Open Catalyst 2022 (OC22) Dataset and Challenges for Oxide Electrocatalysts | D39: 2023 | E39: Benchmark-supporting dataset | F39: Supporting | G39: Foundation datasets and model ecosystems | H39: Oxide surfaces and adsorbates | I39: Structure-to-energy/forces; relaxation for oxide electrocatalysis | J39: OC22 baselines | K39: Energy/force errors; relaxation metrics | L39: DFT | M39: 10.1021/acscatal.2c05426 | N39: https://doi.org/10.1021/acscatal.2c05426 | O39: https://github.com/FAIR-Chem/fairchem | Q39: Yes | R39: Yes | S39: New literature sweep; web-verified | T39: A | U39: 2026-09-29 | V39: No | W39: Medium | X39: Large oxide electrocatalysis dataset and challenge.
A40: N024 | C40: SPICE, A Dataset of Drug-like Molecules and Peptides for Training Machine Learning Potentials | D40: 2023 | E40: Benchmark-supporting dataset | F40: Supporting | G40: Foundation datasets and model ecosystems | H40: Drug-like molecules, peptides, dimers | I40: Molecular energy/force training and benchmark data | J40: Molecular ML potentials | K40: Energy/force errors across chemical space | L40: Quantum chemistry | M40: 10.1038/s41597-022-01882-6 | N40: https://doi.org/10.1038/s41597-022-01882-6 | O40: https://github.com/openmm/spice-dataset | Q40: Yes | R40: Yes | S40: New literature sweep; web-verified | T40: A | U40: 2026-09-29 | V40: No | W40: Medium | X40: More than 1.1 million conformations; broad molecular chemistry coverage.
...

Sheet Taxonomy
A1: Primary_Category | B1: Definition / evaluation question | C1: Record_Count
A2: General and foundation MLIP evaluation | B2: How transferable are general-purpose/foundation potentials? | C2: 29
A3: Foundation datasets and model ecosystems | B3: Which datasets/models underpin current foundation-potential benchmarks? | C3: 15
A4: Methodology, reliability and efficiency | B4: How should errors, UQ, OOD behavior, speed and cost be measured? | C4: 13
A5: Surfaces, interfaces and catalysis | B5: Do models transfer to under-coordinated and interfacial environments? | C5: 12
A6: Molecules, reactions and chemical kinetics | B6: Are molecular PESs, reactions and kinetics quantitatively reliable? | C6: 10
A7: Benchmark suites and platforms | B7: Can models be compared under a standardized reusable protocol? | C7: 9
A8: Phonons, vibrations and thermal | B8: Are harmonic/anharmonic vibrations and heat transport correct? | C8: 8
A9: Batteries, diffusion and ion transport | B9: Are barriers, diffusivities and transport mechanisms correct? | C9: 7
A10: Defects, disorder and dimensionality | B10: How reliable are models in OOD defects, amorphous or reduced-dimensional systems? | C10: 7
A11: Crystal search, stability and generation | B11: Do MLIPs preserve energetic ordering during search/discovery? | C11: 5
A12: MOFs, zeolites and molecular crystals | B12: Can noncovalent/porous crystals be modeled reliably? | C12: 5
A13: Broader atomistic ML benchmarks | B13: Which adjacent atomistic-ML resources inform MLIP evaluation? | C13: 4
... A18: Thermodynamics and phase diagrams | B18: Do MLIPs recover finite-temperature phase stability/topology? | C18: 1
A20: Scope_Tier | B20: Definition
A21: Core | B21: Direct benchmark study, reusable suite/platform, or task-aligned benchmark resource
A22: Supporting | B22: Enabling dataset, methodology, review, or broad model-validation resource
A24: Curation_Confidence | B24: Definition
A25: A | B25: Web-verified in the 2026-09-29 literature sweep; manually classified
A26: B | B26: Imported from existing Zotero bibliography and normalized; classification may be title/known-scope based
